<?xml version="1.0"?>
<robot xmlns:xacro="http://www.ros.org/wiki/xacro">

  <!-- 駆動輪ジョイント＋トランスミッション定義マクロ -->
  <!-- 使用例:
       <xacro:wheel_joint prefix="left" parent="base_link">
         <origin xyz="0.0 0.23 0.15" rpy="${-PI/2} 0 0"/>
         <axis xyz="0 0 1"/>
       </xacro:wheel_joint>
  -->
  <xacro:macro name="wheel_joint" params="prefix parent *origin *axis">
    <!-- ジョイント定義 -->
    <joint name="${prefix}_wheel_joint" type="continuous">
      <parent link="${parent}"/>
      <child link="${prefix}_wheel_link"/>
      <xacro:insert_block name="origin"/>
      <xacro:insert_block name="axis"/>
      <limit effort="10.5" velocity="10.0" lower="${-1e15}" upper="${1e15}"/>
      <dynamics damping="0.05"/>
    </joint>

    <!-- トランスミッション定義 -->
    <transmission name="${prefix}_wheel_transmission">
      <type>transmission_interface/SimpleTransmission</type>

      <joint name="${prefix}_wheel_joint">
        <hardwareInterface>hardware_interface/VelocityJointInterface</hardwareInterface>
      </joint>

      <actuator name="${prefix}_motor">
        <hardwareInterface>hardware_interface/VelocityJointInterface</hardwareInterface>
        <mechanicalReduction>1</mechanicalReduction>
      </actuator>
    </transmission>
  </xacro:macro>

</robot>
