<?xml version="1.0"?>
<sdf version="1.9">
  <!-- モデル定義: orne_box -->
  <model name="orne_box">

    <!-- ベースリンク (ロボット本体) -->
    <link name="base_footprint">

      <!-- 慣性パラメータ -->
      <inertial>
        <pose>0.091102 0 0.176713 0 -0 0</pose>
        <mass>25.4</mass>
        <inertia>
          <ixx>1.22486</ixx>
          <ixy>0</ixy>
          <ixz>0.016878</ixz>
          <iyy>3.58311</iyy>
          <iyz>0</iyz>
          <izz>3.93825</izz>
        </inertia>
      </inertial>

      <!-- 衝突判定: メインボディ -->
      <collision name="base_link_collision">
        <pose>0.09 0 0.1715 0 -0 0</pose>
        <geometry>
          <box>
            <size>0.4 0.404 0.202</size>
          </box>
        </geometry>
      <surface>
        <contact><ode/></contact>
        <friction>
          <ode>
            <mu>0.8</mu>
            <mu2>0.8</mu2>
          </ode>
        </friction>
      </surface>
      </collision>

      <!-- 衝突判定: 上部プレート -->
      <collision name="base_link_collision_1">
        <pose>0.36125 0 0.2625 0 -0 0</pose>
        <geometry>
          <box>
            <size>0.1425 0.404 0.02</size>
          </box>
        </geometry>
      <surface>
        <contact><ode/></contact>
        <friction>
          <ode>
            <mu>0.8</mu>
            <mu2>0.8</mu2>
          </ode>
        </friction>
      </surface>
      </collision>

      <!-- 衝突判定: 下部プレート -->
      <collision name="base_link_collision_2">
        <pose>0.35625 0 0.156 0 -0 0</pose>
        <geometry>
          <box>
            <size>0.1325 0.404 0.02</size>
          </box>
        </geometry>
      <surface>
        <contact><ode/></contact>
        <friction>
          <ode>
            <mu>0.8</mu>
            <mu2>0.8</mu2>
          </ode>
        </friction>
      </surface>
      </collision>

      <!-- 衝突判定: 背面柱 -->
      <collision name="base_link_collision_3">
        <pose>-0.12 0 0.4815 0 -0 0</pose>
        <geometry>
          <box>
            <size>0.02 0.404 0.822</size>
          </box>
        </geometry>
      <surface>
        <contact><ode/></contact>
        <friction>
          <ode>
            <mu>0.8</mu>
            <mu2>0.8</mu2>
          </ode>
        </friction>
      </surface>
      </collision>

      <!-- 衝突判定: Livoxセンサ用メッシュ -->
      <collision name="Livox_Mid360_link_collision">
        <pose>-0.08 0 0.85 0 -0 0</pose>
        <geometry>
          <mesh>
            <scale>0.001 0.001 0.001</scale>
            <uri>package://simulator/models/orne_box/meshes/livox_mid360.stl</uri>
          </mesh>
        </geometry>
        <surface>
          <contact><ode/></contact>
          <friction><ode/></friction>
        </surface>
      </collision>

      <!-- 可視化: メインボディ（オレンジ） -->
      <visual name="base_link_visual">
        <pose>0.09 0 0.1715 0 -0 0</pose>
        <geometry>
          <box>
            <size>0.4 0.404 0.202</size>
          </box>
        </geometry>
        
        <material>
          <ambient>1.0 0.5 0.0 1</ambient>
          <diffuse>1.0 0.5 0.0 1</diffuse>
          <specular>0.1 0.1 0.1 1</specular>
          <emissive>0 0 0 1</emissive>
        </material>
      <specular>0.1 0.1 0.1 1</specular>
  <emissive>0 0 0 1</emissive>

      </visual>

      <!-- 可視化: 上部プレート（オレンジ） -->
      <visual name="base_link_visual_1">
        <pose>0.36125 0 0.2625 0 -0 0</pose>
        <geometry>
          <box>
            <size>0.1425 0.404 0.02</size>
          </box>
        </geometry>
        
        <material>
          <ambient>1.0 0.5 0.0 1</ambient>
          <diffuse>1.0 0.5 0.0 1</diffuse>
          <specular>0.1 0.1 0.1 1</specular>
          <emissive>0 0 0 1</emissive>
        </material>
      <specular>0.1 0.1 0.1 1</specular>
  <emissive>0 0 0 1</emissive>

      </visual>

      <!-- 可視化: 下部プレート（オレンジ） -->
      <visual name="base_link_visual_2">
        <pose>0.35625 0 0.156 0 -0 0</pose>
        <geometry>
          <box>
            <size>0.1325 0.404 0.02</size>
          </box>
        </geometry>
        
        <material>
          <ambient>1.0 0.5 0.0 1</ambient>
          <diffuse>1.0 0.5 0.0 1</diffuse>
          <specular>0.1 0.1 0.1 1</specular>
          <emissive>0 0 0 1</emissive>
        </material>
      <specular>0.1 0.1 0.1 1</specular>
  <emissive>0 0 0 1</emissive>

      </visual>

      <!-- 可視化: 背面柱（オレンジ） -->
      <visual name="base_link_visual_3">
        <pose>-0.12 0 0.4815 0 -0 0</pose>
        <geometry>
          <box>
            <size>0.02 0.404 0.822</size>
          </box>
        </geometry>
        
        <material>
          <ambient>1.0 0.5 0.0 1</ambient>
          <diffuse>1.0 0.5 0.0 1</diffuse>
          <specular>0.1 0.1 0.1 1</specular>
          <emissive>0 0 0 1</emissive>
        </material>
      <specular>0.1 0.1 0.1 1</specular>
  <emissive>0 0 0 1</emissive>

      </visual>

      <!-- 可視化: Livox Mid360（青） -->
      <visual name="Livox_Mid360_link_visual">
        <pose>-0.08 0 0.85 1.57079 -0 3.14159</pose>
        <geometry>
          <mesh>
            <scale>0.001 0.001 0.001</scale>
            <uri>package://simulator/models/orne_box/meshes/livox_mid360.stl</uri>
          </mesh>
        </geometry>
        
        <material>
          <ambient>0.0 0.0 1.0 1</ambient>
          <diffuse>0.0 0.0 1.0 1</diffuse>
          <specular>0.1 0.1 0.1 1</specular>
          <emissive>0 0 0 1</emissive>
        </material>
      <specular>0.1 0.1 0.1 1</specular>
  <emissive>0 0 0 1</emissive>

      </visual>

      <!-- 可視化: Hokuyo（青） -->
      <visual name="hokuyo_link_visual">
        <pose>0.36 0 0.18 0 -0 0</pose>
        <geometry>
          <box>
            <size>0.05 0.05 0.07</size>
          </box>
        </geometry>
        
        <material>
          <ambient>0.0 0.0 1.0 1</ambient>
          <diffuse>0.0 0.0 1.0 1</diffuse>
          <specular>0.1 0.1 0.1 1</specular>
          <emissive>0 0 0 1</emissive>
        </material>
      <specular>0.1 0.1 0.1 1</specular>
  <emissive>0 0 0 1</emissive>

      </visual>

      <!-- 可視化: ZEDカメラ（青） -->
      <visual name="zed_camera_center_visual">
        <pose>0 0 0.8 0 -0 0</pose>
        <geometry>
          <box>
            <size>0.033 0.175 0.03</size>
          </box>
        </geometry>
        
        <material>
          <ambient>0.0 0.0 1.0 1</ambient>
          <diffuse>0.0 0.0 1.0 1</diffuse>
          <specular>0.1 0.1 0.1 1</specular>
          <emissive>0 0 0 1</emissive>
        </material>
      <specular>0.1 0.1 0.1 1</specular>
  <emissive>0 0 0 1</emissive>

      </visual>

      <!-- センサ: Livox Mid360 LiDAR -->
      <sensor name="Livox_Mid360" type="gpu_lidar">
        <topic>livox/lidar</topic>
        <update_rate>10</update_rate>
        <lidar>
          <scan>
            <horizontal>
              <samples>3600</samples>
              <resolution>1</resolution>
              <min_angle>-3.14</min_angle>
              <max_angle>3.14</max_angle>
            </horizontal>
            <vertical>
              <samples>59</samples>
              <resolution>1</resolution>
              <min_angle>-0.122</min_angle>
              <max_angle>0.907</max_angle>
            </vertical>
          </scan>
          <range>
            <min>0.1</min>
            <max>40</max>
            <resolution>0.01</resolution>
          </range>
          <frame_id>/Livox_Mid360_link</frame_id>
        </lidar>
        <visualize>true</visualize>
        <pose>-0.08 0 0.85 0 -0 0</pose>
        <ignition_frame_id>Livox_Mid360_link</ignition_frame_id>
        <alwaysOn>1</alwaysOn>
      </sensor>

      <!-- センサ: IMU（Livox一体型） -->
      <sensor name="imu_sensor" type="imu">
        <topic>livox/imu</topic>
        <update_rate>100</update_rate>
        <always_on>1</always_on>
        <visualize>0</visualize>
        <pose>-0.08 0 0.85 0 -0 0</pose>
        <ignition_frame_id>Livox_Mid360_link</ignition_frame_id>
      </sensor>

      <!-- センサ: Hokuyo LiDAR -->
      <sensor name="hokuyo" type="gpu_lidar">
        <topic>scan</topic>
        <update_rate>40</update_rate>
        <lidar>
          <scan>
            <horizontal>
              <samples>1080</samples>
              <resolution>1</resolution>
              <min_angle>-1.57</min_angle>
              <max_angle>1.57</max_angle>
            </horizontal>
            <vertical>
              <samples>1</samples>
              <resolution>0.1</resolution>
              <min_angle>0</min_angle>
              <max_angle>0</max_angle>
            </vertical>
          </scan>
          <range>
            <min>0.1</min>
            <max>30</max>
            <resolution>0.01</resolution>
          </range>
          <frame_id>/hokuyo_link</frame_id>
        </lidar>
        <visualize>true</visualize>
        <pose>0.36 0 0.18 0 -0 0</pose>
        <ignition_frame_id>hokuyo_link</ignition_frame_id>
        <alwaysOn>1</alwaysOn>
      </sensor>

      <!-- センサ: ZEDカメラ -->
      <sensor name="zed_camera" type="camera">
        <camera>
          <horizontal_fov>1.047</horizontal_fov>
          <image>
            <width>480</width>
            <height>300</height>
            <format>R8G8B8</format>
          </image>
          <clip>
            <near>0.02</near>
            <far>300</far>
          </clip>
        </camera>
        <always_on>1</always_on>
        <update_rate>10</update_rate>
        <visualize>1</visualize>
        <topic>image_raw</topic>
        <pose>0 0 0.8 0 -0 0</pose>
        <ignition_frame_id>zed_camera_center</ignition_frame_id>
      </sensor>

    </link> <!-- base_footprint 終了 -->

    <!-- 左キャスター：旋回ジョイント -->
    <joint name="left_caster_swivel_joint" type="revolute">
      <pose relative_to="base_footprint">0.362 0.15 0.115 0 -0 0</pose>
      <parent>base_footprint</parent>
      <child>left_caster_swivel_link</child>
      <axis>
        <xyz>0 0 1</xyz>
        <limit>
          <effort>0</effort>
          <velocity>0</velocity>
          <lower>-1e+16</lower>
          <upper>1e+16</upper>
        </limit>
        <dynamics>
          <damping>0.01</damping>
          <friction>0</friction>
          <spring_reference>0</spring_reference>
          <spring_stiffness>0</spring_stiffness>
        </dynamics>
      </axis>
    </joint>

    <!-- 左キャスター：旋回リンク -->
    <link name="left_caster_swivel_link">
      <pose relative_to="left_caster_swivel_joint">0 0 0 0 -0 0</pose>
      <inertial>
        <pose>0 0 0 0 -0 0</pose>
        <mass>0.1</mass>
        <inertia>
          <ixx>0.001</ixx>
          <ixy>0</ixy>
          <ixz>0</ixz>
          <iyy>0.001</iyy>
          <iyz>0</iyz>
          <izz>0.001</izz>
        </inertia>
      </inertial>
      <collision name="left_caster_swivel_link_collision">
        <pose>0 0 0 0 -0 0</pose>
        <geometry>
          <box>
            <size>0.05 0.05 0.01</size>
          </box>
        </geometry>
      <surface>
        <contact><ode/></contact>
        <friction>
          <ode>
            <mu>0.8</mu>
            <mu2>0.8</mu2>
          </ode>
        </friction>
      </surface>
      </collision>
      <visual name="left_caster_swivel_link_visual">
        <pose>0 0 0 0 -0 0</pose>
        <geometry>
          <box>
            <size>0.05 0.05 0.01</size>
          </box>
        </geometry>
        
        <material>
          <ambient>0.0 0.0 0.0 1</ambient>
          <diffuse>0.0 0.0 0.0 1</diffuse>
          <specular>0.1 0.1 0.1 1</specular>
          <emissive>0 0 0 1</emissive>
        </material>
      <specular>0.1 0.1 0.1 1</specular>
  <emissive>0 0 0 1</emissive>

      </visual>
    </link>

    <!-- 左キャスター：ホイールジョイント -->
    <joint name="left_caster_wheel_joint" type="revolute">
      <pose relative_to="left_caster_swivel_link">0.03 0 -0.065 -1.5708 0 0</pose>
      <parent>left_caster_swivel_link</parent>
      <child>left_caster_wheel_link</child>
      <axis>
        <xyz>0 0 1</xyz>
        <limit>
          <effort>0</effort>
          <velocity>0</velocity>
          <lower>-1e+16</lower>
          <upper>1e+16</upper>
        </limit>
        <dynamics>
          <damping>0.01</damping>
          <friction>0</friction>
          <spring_reference>0</spring_reference>
          <spring_stiffness>0</spring_stiffness>
        </dynamics>
      </axis>
    </joint>

    <!-- 左キャスター：ホイールリンク -->
    <link name="left_caster_wheel_link">
      <pose relative_to="left_caster_wheel_joint">0 0 0 0 -0 0</pose>
      <inertial>
        <pose>0 0 0 0 -0 0</pose>
        <mass>0.2</mass>
        <inertia>
          <ixx>0.001</ixx>
          <ixy>0</ixy>
          <ixz>0</ixz>
          <iyy>0.001</iyy>
          <iyz>0</iyz>
          <izz>0.001</izz>
        </inertia>
      </inertial>
      <collision name="left_caster_wheel_link_collision">
        <pose>0 0 0 0 -0 0</pose>
        <geometry>
          <cylinder>
            <length>0.025</length>
            <radius>0.05</radius>
          </cylinder>
        </geometry>
      <surface>
        <contact><ode/></contact>
        <friction>
          <ode>
            <mu>0.8</mu>
            <mu2>0.8</mu2>
          </ode>
        </friction>
      </surface>
      </collision>
      <visual name="left_caster_wheel_link_visual">
        <pose>0 0 0 0 -0 0</pose>
        <geometry>
          <cylinder>
            <length>0.025</length>
            <radius>0.05</radius>
          </cylinder>
        </geometry>
        
        <material>
          <ambient>0.0 0.0 0.0 1</ambient>
          <diffuse>0.0 0.0 0.0 1</diffuse>
          <specular>0.1 0.1 0.1 1</specular>
          <emissive>0 0 0 1</emissive>
        </material>
      <specular>0.1 0.1 0.1 1</specular>
  <emissive>0 0 0 1</emissive>

      </visual>
    </link>

    <!-- 左駆動輪：ジョイント -->
    <joint name="left_wheel_joint" type="revolute">
      <pose relative_to="base_footprint">0 0.23075 0.152 -1.5708 0 0</pose>
      <parent>base_footprint</parent>
      <child>left_wheel_link</child>
      <axis>
        <xyz>0 0 1</xyz>
        <limit>
          <effort>10.5</effort>       <!-- 最大トルク -->
          <velocity>10</velocity>     <!-- 最大回転速度 -->
          <lower>-1e+16</lower>       <!-- 回転範囲（無制限） -->
          <upper>1e+16</upper>
        </limit>
        <dynamics>
          <damping>0.05</damping>     <!-- 減衰係数 -->
          <friction>0</friction>
          <spring_reference>0</spring_reference>
          <spring_stiffness>0</spring_stiffness>
        </dynamics>
      </axis>
    </joint>

    <!-- 左駆動輪：リンク -->
    <link name="left_wheel_link">
      <pose relative_to="left_wheel_joint">0 0 0 0 -0 0</pose>
      <inertial>
        <pose>0 0 0 0 -0 0</pose>
        <mass>0.15</mass>
        <inertia>
          <ixx>0.005</ixx>
          <ixy>0</ixy>
          <ixz>0</ixz>
          <iyy>0.005</iyy>
          <iyz>0</iyz>
          <izz>0.01</izz>
        </inertia>
      </inertial>
      <collision name="left_wheel_link_collision">
        <pose>0 0 0 0 -0 0</pose>
        <geometry>
          <cylinder>
            <length>0.045</length>    <!-- 幅 -->
            <radius>0.152</radius>    <!-- 半径 -->
          </cylinder>
        </geometry>
      <surface>
        <contact><ode/></contact>
        <friction>
          <ode>
            <mu>0.8</mu>
            <mu2>0.8</mu2>
          </ode>
        </friction>
      </surface>
      </collision>
      <visual name="left_wheel_link_visual">
        <pose>0 0 0 0 -0 0</pose>
        <geometry>
          <cylinder>
            <length>0.045</length>
            <radius>0.152</radius>
          </cylinder>
        </geometry>
        
        <material>
          <ambient>0.0 0.0 0.0 1</ambient>
          <diffuse>0.0 0.0 0.0 1</diffuse>
          <specular>0.1 0.1 0.1 1</specular>
          <emissive>0 0 0 1</emissive>
        </material>
      <specular>0.1 0.1 0.1 1</specular>
  <emissive>0 0 0 1</emissive>

      </visual>
    </link>

    <!-- 右キャスター：旋回ジョイント -->
    <joint name="right_caster_swivel_joint" type="revolute">
      <pose relative_to="base_footprint">0.362 -0.15 0.115 0 -0 0</pose>
      <parent>base_footprint</parent>
      <child>right_caster_swivel_link</child>
      <axis>
        <xyz>0 0 1</xyz>
        <limit>
          <effort>0</effort>
          <velocity>0</velocity>
          <lower>-1e+16</lower>
          <upper>1e+16</upper>
        </limit>
        <dynamics>
          <damping>0.01</damping>
          <friction>0</friction>
          <spring_reference>0</spring_reference>
          <spring_stiffness>0</spring_stiffness>
        </dynamics>
      </axis>
    </joint>

    <!-- 右キャスター：旋回リンク -->
    <link name="right_caster_swivel_link">
      <pose relative_to="right_caster_swivel_joint">0 0 0 0 -0 0</pose>
      <inertial>
        <pose>0 0 0 0 -0 0</pose>
        <mass>0.1</mass>
        <inertia>
          <ixx>0.001</ixx>
          <ixy>0</ixy>
          <ixz>0</ixz>
          <iyy>0.001</iyy>
          <iyz>0</iyz>
          <izz>0.001</izz>
        </inertia>
      </inertial>
      <collision name="right_caster_swivel_link_collision">
        <pose>0 0 0 0 -0 0</pose>
        <geometry>
          <box>
            <size>0.05 0.05 0.01</size>
          </box>
        </geometry>
      <surface>
        <contact><ode/></contact>
        <friction>
          <ode>
            <mu>0.8</mu>
            <mu2>0.8</mu2>
          </ode>
        </friction>
      </surface>
      </collision>
      <visual name="right_caster_swivel_link_visual">
        <pose>0 0 0 0 -0 0</pose>
        <geometry>
          <box>
            <size>0.05 0.05 0.01</size>
          </box>
        </geometry>
        
        <material>
          <ambient>0.0 0.0 0.0 1</ambient>
          <diffuse>0.0 0.0 0.0 1</diffuse>
          <specular>0.1 0.1 0.1 1</specular>
          <emissive>0 0 0 1</emissive>
        </material>
      <specular>0.1 0.1 0.1 1</specular>
  <emissive>0 0 0 1</emissive>

      </visual>
    </link>

    <!-- 右キャスター：ホイールジョイント -->
    <joint name="right_caster_wheel_joint" type="revolute">
      <pose relative_to="right_caster_swivel_link">0.03 0 -0.065 -1.5708 0 0</pose>
      <parent>right_caster_swivel_link</parent>
      <child>right_caster_wheel_link</child>
      <axis>
        <xyz>0 0 1</xyz>
        <limit>
          <effort>0</effort>
          <velocity>0</velocity>
          <lower>-1e+16</lower>
          <upper>1e+16</upper>
        </limit>
        <dynamics>
          <damping>0.01</damping>
          <friction>0</friction>
          <spring_reference>0</spring_reference>
          <spring_stiffness>0</spring_stiffness>
        </dynamics>
      </axis>
    </joint>

    <!-- 右キャスター：ホイールリンク -->
    <link name="right_caster_wheel_link">
      <pose relative_to="right_caster_wheel_joint">0 0 0 0 -0 0</pose>
      <inertial>
        <pose>0 0 0 0 -0 0</pose>
        <mass>0.2</mass>
        <inertia>
          <ixx>0.001</ixx>
          <ixy>0</ixy>
          <ixz>0</ixz>
          <iyy>0.001</iyy>
          <iyz>0</iyz>
          <izz>0.001</izz>
        </inertia>
      </inertial>
      <collision name="right_caster_wheel_link_collision">
        <pose>0 0 0 0 -0 0</pose>
        <geometry>
          <cylinder>
            <length>0.025</length>
            <radius>0.05</radius>
          </cylinder>
        </geometry>
      <surface>
        <contact><ode/></contact>
        <friction>
          <ode>
            <mu>0.8</mu>
            <mu2>0.8</mu2>
          </ode>
        </friction>
      </surface>
      </collision>
      <visual name="right_caster_wheel_link_visual">
        <pose>0 0 0 0 -0 0</pose>
        <geometry>
          <cylinder>
            <length>0.025</length>
            <radius>0.05</radius>
          </cylinder>
        </geometry>
        
        <material>
          <ambient>0.0 0.0 0.0 1</ambient>
          <diffuse>0.0 0.0 0.0 1</diffuse>
          <specular>0.1 0.1 0.1 1</specular>
          <emissive>0 0 0 1</emissive>
        </material>
      <specular>0.1 0.1 0.1 1</specular>
  <emissive>0 0 0 1</emissive>

      </visual>
    </link>

    <!-- 右駆動輪：ジョイント -->
    <joint name="right_wheel_joint" type="revolute">
      <pose relative_to="base_footprint">0 -0.23075 0.152 -1.5708 0 0</pose>
      <parent>base_footprint</parent>
      <child>right_wheel_link</child>
      <axis>
        <xyz>0 0 1</xyz>
        <limit>
          <effort>10.5</effort>       <!-- 最大トルク -->
          <velocity>10</velocity>     <!-- 最大回転速度 -->
          <lower>-1e+16</lower>       <!-- 回転範囲（無制限） -->
          <upper>1e+16</upper>
        </limit>
        <dynamics>
          <damping>0.05</damping>     <!-- 減衰係数 -->
          <friction>0</friction>
          <spring_reference>0</spring_reference>
          <spring_stiffness>0</spring_stiffness>
        </dynamics>
      </axis>
    </joint>

    <!-- 右駆動輪：リンク -->
    <link name="right_wheel_link">
      <pose relative_to="right_wheel_joint">0 0 0 0 -0 0</pose>
      <inertial>
        <pose>0 0 0 0 -0 0</pose>
        <mass>0.15</mass>
        <inertia>
          <ixx>0.005</ixx>
          <ixy>0</ixy>
          <ixz>0</ixz>
          <iyy>0.005</iyy>
          <iyz>0</iyz>
          <izz>0.01</izz>
        </inertia>
      </inertial>
      <collision name="right_wheel_link_collision">
        <pose>0 0 0 0 -0 0</pose>
        <geometry>
          <cylinder>
            <length>0.045</length>    <!-- タイヤの幅 -->
            <radius>0.152</radius>    <!-- タイヤの半径 -->
          </cylinder>
        </geometry>
      <surface>
        <contact><ode/></contact>
        <friction>
          <ode>
            <mu>0.8</mu>
            <mu2>0.8</mu2>
          </ode>
        </friction>
      </surface>
      </collision>
      <visual name="right_wheel_link_visual">
        <pose>0 0 0 0 -0 0</pose>
        <geometry>
          <cylinder>
            <length>0.045</length>
            <radius>0.152</radius>
          </cylinder>
        </geometry>
        
        <material>
          <ambient>0.0 0.0 0.0 1</ambient>
          <diffuse>0.0 0.0 0.0 1</diffuse>
          <specular>0.1 0.1 0.1 1</specular>
          <emissive>0 0 0 1</emissive>
        </material>
      <specular>0.1 0.1 0.1 1</specular>
  <emissive>0 0 0 1</emissive>

      </visual>
    </link>

    <!-- 差動二輪駆動プラグイン -->
    <plugin name="ignition::gazebo::systems::DiffDrive" filename="libignition-gazebo-diff-drive-system.so">
      <left_joint>left_wheel_joint</left_joint>         <!-- 左駆動輪ジョイント -->
      <right_joint>right_wheel_joint</right_joint>      <!-- 右駆動輪ジョイント -->
      <wheel_separation>0.4615</wheel_separation>       <!-- 左右の車輪間の距離 -->
      <wheel_radius>0.145</wheel_radius>                <!-- 車輪の半径 -->
      <odom_publish_frequency>0.1</odom_publish_frequency> <!-- オドメトリの発行頻度 [Hz] -->
      <topic>cmd_vel</topic>                            <!-- 入力速度トピック名 -->
    </plugin>

    <!-- センサープラグイン（GPUレンダリング用） -->
    <plugin name="ignition::gazebo::systems::Sensors" filename="ignition-gazebo-sensors-system">
      <render_engine>ogre2</render_engine>              <!-- レンダリングエンジン -->
    </plugin>

    <!-- モデルの静的状態（false: 移動可能） -->
    <static>0</static>

  </model>
</sdf>